Failure # 1 (occurred at 2020-01-08_16-55-04)
Traceback (most recent call last):
  File "/usr/local/lib/python3.6/dist-packages/ray/tune/trial_runner.py", line 426, in _process_trial
    result = self.trial_executor.fetch_result(trial)
  File "/usr/local/lib/python3.6/dist-packages/ray/tune/ray_trial_executor.py", line 378, in fetch_result
    result = ray.get(trial_future[0], DEFAULT_GET_TIMEOUT)
  File "/usr/local/lib/python3.6/dist-packages/ray/worker.py", line 1457, in get
    raise value.as_instanceof_cause()
ray.exceptions.RayTaskError: [36mray::ARSTrainer.train()[39m (pid=38001, ip=172.18.0.6)
  File "python/ray/_raylet.pyx", line 636, in ray._raylet.execute_task
  File "python/ray/_raylet.pyx", line 619, in ray._raylet.execute_task.function_executor
  File "/usr/local/lib/python3.6/dist-packages/ray/rllib/agents/trainer.py", line 444, in train
    raise e
  File "/usr/local/lib/python3.6/dist-packages/ray/rllib/agents/trainer.py", line 433, in train
    result = Trainable.train(self)
  File "/usr/local/lib/python3.6/dist-packages/ray/tune/trainable.py", line 176, in train
    result = self._train()
  File "/usr/local/lib/python3.6/dist-packages/ray/rllib/agents/ars/ars.py", line 211, in _train
    theta_id, config["num_rollouts"])
  File "/usr/local/lib/python3.6/dist-packages/ray/rllib/agents/ars/ars.py", line 316, in _collect_results
    for result in ray_get_and_free(rollout_ids):
  File "/usr/local/lib/python3.6/dist-packages/ray/rllib/utils/memory.py", line 33, in ray_get_and_free
    result = ray.get(object_ids)
ray.exceptions.RayTaskError: [36mray::Worker.do_rollouts()[39m (pid=37986, ip=172.18.0.6)
  File "python/ray/_raylet.pyx", line 636, in ray._raylet.execute_task
  File "python/ray/_raylet.pyx", line 619, in ray._raylet.execute_task.function_executor
  File "/usr/local/lib/python3.6/dist-packages/ray/rllib/agents/ars/ars.py", line 143, in do_rollouts
    rewards_neg, lengths_neg = self.rollout(timestep_limit)
  File "/usr/local/lib/python3.6/dist-packages/ray/rllib/agents/ars/ars.py", line 112, in rollout
    offset=self.config["offset"])
  File "/usr/local/lib/python3.6/dist-packages/ray/rllib/agents/ars/policies.py", line 49, in rollout
    observation, rew, done, _ = env.step(ac)
  File "/root/hany606/Tensegrity-Robotics/src/dev/gym-tensegrity/gym_tensegrity/envs/jumper_env.py", line 120, in step
    self._takeAction(action)
  File "/root/hany606/Tensegrity-Robotics/src/dev/gym-tensegrity/gym_tensegrity/envs/jumper_env.py", line 164, in _takeAction
    raise Exception("The provided action is out of allowed space.")
Exception: The provided action is out of allowed space.

