Failure # 1 (occurred at 2020-01-29_08-46-26)
Traceback (most recent call last):
  File "/usr/local/lib/python3.6/dist-packages/ray/tune/trial_runner.py", line 426, in _process_trial
    result = self.trial_executor.fetch_result(trial)
  File "/usr/local/lib/python3.6/dist-packages/ray/tune/ray_trial_executor.py", line 378, in fetch_result
    result = ray.get(trial_future[0], DEFAULT_GET_TIMEOUT)
  File "/usr/local/lib/python3.6/dist-packages/ray/worker.py", line 1457, in get
    raise value.as_instanceof_cause()
ray.exceptions.RayTaskError(NotImplementedError): [36mray::ARSTrainer.train()[39m (pid=81300, ip=172.18.0.6)
  File "/usr/local/lib/python3.6/dist-packages/ray/tune/trainable.py", line 176, in train
    result = self._train()
  File "/usr/local/lib/python3.6/dist-packages/ray/rllib/agents/ars/ars.py", line 211, in _train
    theta_id, config["num_rollouts"])
  File "/usr/local/lib/python3.6/dist-packages/ray/rllib/agents/ars/ars.py", line 316, in _collect_results
    for result in ray_get_and_free(rollout_ids):
  File "/usr/local/lib/python3.6/dist-packages/ray/rllib/utils/memory.py", line 33, in ray_get_and_free
    result = ray.get(object_ids)
ray.exceptions.RayTaskError(ValueError): [36mray::Worker.do_rollouts()[39m (pid=81349, ip=172.18.0.6)
  File "python/ray/_raylet.pyx", line 636, in ray._raylet.execute_task
  File "python/ray/_raylet.pyx", line 619, in ray._raylet.execute_task.function_executor
  File "/usr/local/lib/python3.6/dist-packages/ray/rllib/agents/ars/ars.py", line 140, in do_rollouts
    rewards_pos, lengths_pos = self.rollout(timestep_limit)
  File "/usr/local/lib/python3.6/dist-packages/ray/rllib/agents/ars/ars.py", line 112, in rollout
    offset=self.config["offset"])
  File "/usr/local/lib/python3.6/dist-packages/ray/rllib/agents/ars/policies.py", line 48, in rollout
    ac = policy.compute(observation, add_noise=add_noise, update=True)[0]
  File "/usr/local/lib/python3.6/dist-packages/ray/rllib/agents/ars/policies.py", line 96, in compute
    observation = self.preprocessor.transform(observation)
  File "/usr/local/lib/python3.6/dist-packages/ray/rllib/models/preprocessors.py", line 166, in transform
    self.check_shape(observation)
  File "/usr/local/lib/python3.6/dist-packages/ray/rllib/models/preprocessors.py", line 65, in check_shape
    self._obs_space, observation)
ValueError: ('Observation outside expected value range', Box(44,), array([ 3.49019344e+00,  3.58695472e+00,  4.90862964e+00, -3.21913692e+00,
       -3.82822387e+00,  4.91220598e+00, -3.22468113e+00, -3.82794413e+00,
       -4.90890701e+00,  3.48464923e+00,  3.58723445e+00, -4.91248336e+00,
        6.86948968e+00, -5.06469271e+00,  1.53549714e-01, -8.34986020e+00,
        7.91110742e+00,  1.53566169e-01,  1.20249565e+02,  5.24661857e+02,
       -1.40741713e+01,  9.29365837e+01,  5.49284605e+02, -1.04978279e+01,
        8.73923728e+01,  5.49564338e+02, -1.04962590e+01,  1.14705354e+02,
        5.24941590e+02, -1.40726024e+01, -5.60657623e+02,  2.05018622e+03,
       -1.81698216e-02, -9.00404843e+02,  1.66195162e+03, -1.71510117e-03,
        7.95000000e+00,  7.95000000e+00,  7.95000000e+00,  7.95000000e+00,
        7.95000000e+00,  7.95000000e+00,  7.95000000e+00,  7.95000000e+00]))

During handling of the above exception, another exception occurred:

[36mray::ARSTrainer.train()[39m (pid=81300, ip=172.18.0.6)
  File "python/ray/_raylet.pyx", line 633, in ray._raylet.execute_task
  File "python/ray/_raylet.pyx", line 634, in ray._raylet.execute_task
  File "python/ray/_raylet.pyx", line 636, in ray._raylet.execute_task
  File "python/ray/_raylet.pyx", line 619, in ray._raylet.execute_task.function_executor
  File "/usr/local/lib/python3.6/dist-packages/ray/rllib/agents/trainer.py", line 438, in train
    self._try_recover()
  File "/usr/local/lib/python3.6/dist-packages/ray/rllib/agents/trainer.py", line 799, in _try_recover
    "Recovery is not supported for this algorithm")
NotImplementedError: Recovery is not supported for this algorithm

