Failure # 1 (occurred at 2020-02-27_21-14-27)
Traceback (most recent call last):
  File "/usr/local/lib/python3.6/dist-packages/ray/tune/ray_trial_executor.py", line 222, in start_trial
    self._start_trial(trial, checkpoint, remote_runner)
  File "/usr/local/lib/python3.6/dist-packages/ray/tune/ray_trial_executor.py", line 156, in _start_trial
    self.restore(trial, checkpoint)
  File "/usr/local/lib/python3.6/dist-packages/ray/tune/ray_trial_executor.py", line 608, in restore
    DEFAULT_GET_TIMEOUT)
  File "/usr/local/lib/python3.6/dist-packages/ray/worker.py", line 1457, in get
    raise value.as_instanceof_cause()
ray.exceptions.RayTaskError(KeyError): [36mray::ARSTrainer.__init__()[39m (pid=42865, ip=172.18.0.6)
  File "python/ray/_raylet.pyx", line 626, in ray._raylet.execute_task
  File "python/ray/_raylet.pyx", line 633, in ray._raylet.execute_task
  File "python/ray/_raylet.pyx", line 634, in ray._raylet.execute_task
  File "python/ray/_raylet.pyx", line 636, in ray._raylet.execute_task
  File "python/ray/_raylet.pyx", line 619, in ray._raylet.execute_task.function_executor
  File "/usr/local/lib/python3.6/dist-packages/ray/rllib/agents/trainer.py", line 398, in __init__
    Trainable.__init__(self, config, logger_creator)
  File "/usr/local/lib/python3.6/dist-packages/ray/tune/trainable.py", line 96, in __init__
    self._setup(copy.deepcopy(self.config))
  File "/usr/local/lib/python3.6/dist-packages/ray/rllib/agents/trainer.py", line 523, in _setup
    self._init(self.config, self.env_creator)
  File "/root/hany606/Tensegrity-Robotics/src/dev/gym-tensegrity/learning_scripts/rllib/lib_mod/ars.py", line 166, in _init
    if config["use_pytorch"]:
KeyError: 'use_pytorch'

Failure # 2 (occurred at 2020-02-27_21-14-30)
Traceback (most recent call last):
  File "/usr/local/lib/python3.6/dist-packages/ray/tune/trial_runner.py", line 426, in _process_trial
    result = self.trial_executor.fetch_result(trial)
  File "/usr/local/lib/python3.6/dist-packages/ray/tune/ray_trial_executor.py", line 378, in fetch_result
    result = ray.get(trial_future[0], DEFAULT_GET_TIMEOUT)
  File "/usr/local/lib/python3.6/dist-packages/ray/worker.py", line 1457, in get
    raise value.as_instanceof_cause()
ray.exceptions.RayTaskError(KeyError): [36mray::ARSTrainer.__init__()[39m (pid=42918, ip=172.18.0.6)
  File "python/ray/_raylet.pyx", line 626, in ray._raylet.execute_task
  File "python/ray/_raylet.pyx", line 633, in ray._raylet.execute_task
  File "python/ray/_raylet.pyx", line 634, in ray._raylet.execute_task
  File "python/ray/_raylet.pyx", line 636, in ray._raylet.execute_task
  File "python/ray/_raylet.pyx", line 619, in ray._raylet.execute_task.function_executor
  File "/usr/local/lib/python3.6/dist-packages/ray/rllib/agents/trainer.py", line 398, in __init__
    Trainable.__init__(self, config, logger_creator)
  File "/usr/local/lib/python3.6/dist-packages/ray/tune/trainable.py", line 96, in __init__
    self._setup(copy.deepcopy(self.config))
  File "/usr/local/lib/python3.6/dist-packages/ray/rllib/agents/trainer.py", line 523, in _setup
    self._init(self.config, self.env_creator)
  File "/root/hany606/Tensegrity-Robotics/src/dev/gym-tensegrity/learning_scripts/rllib/lib_mod/ars.py", line 166, in _init
    if config["use_pytorch"]:
KeyError: 'use_pytorch'

