Failure # 1 (occurred at 2020-02-27_21-15-22)
Traceback (most recent call last):
  File "/usr/local/lib/python3.6/dist-packages/ray/tune/ray_trial_executor.py", line 222, in start_trial
    self._start_trial(trial, checkpoint, remote_runner)
  File "/usr/local/lib/python3.6/dist-packages/ray/tune/ray_trial_executor.py", line 156, in _start_trial
    self.restore(trial, checkpoint)
  File "/usr/local/lib/python3.6/dist-packages/ray/tune/ray_trial_executor.py", line 613, in restore
    ray.get(trial.runner.restore.remote(value))
  File "/usr/local/lib/python3.6/dist-packages/ray/worker.py", line 1457, in get
    raise value.as_instanceof_cause()
ray.exceptions.RayTaskError(FileNotFoundError): [36mray::ARSTrainer.restore()[39m (pid=49937, ip=172.18.0.6)
  File "python/ray/_raylet.pyx", line 636, in ray._raylet.execute_task
  File "python/ray/_raylet.pyx", line 619, in ray._raylet.execute_task.function_executor
  File "/usr/local/lib/python3.6/dist-packages/ray/tune/trainable.py", line 327, in restore
    with open(checkpoint_path + ".tune_metadata", "rb") as f:
FileNotFoundError: [Errno 2] No such file or directory: '/root/hany606/Tensegrity-Robotics/src/dev/gym-tensegrity/learning_scripts/rllib/trained_agents/Very_Successfull/train_025_rep_act1_restL/ARS_jumper_29224120_2020-01-21_19-35-20j61sj43o/checkpoint_605/checkpoint-605.tune_metadata'

Failure # 2 (occurred at 2020-02-27_21-15-54)
Traceback (most recent call last):
  File "/usr/local/lib/python3.6/dist-packages/ray/tune/trial_runner.py", line 426, in _process_trial
    result = self.trial_executor.fetch_result(trial)
  File "/usr/local/lib/python3.6/dist-packages/ray/tune/ray_trial_executor.py", line 378, in fetch_result
    result = ray.get(trial_future[0], DEFAULT_GET_TIMEOUT)
  File "/usr/local/lib/python3.6/dist-packages/ray/worker.py", line 1457, in get
    raise value.as_instanceof_cause()
ray.exceptions.RayTaskError(NotImplementedError): [36mray::ARSTrainer.train()[39m (pid=49956, ip=172.18.0.6)
  File "/usr/local/lib/python3.6/dist-packages/ray/tune/trainable.py", line 176, in train
    result = self._train()
  File "/usr/local/lib/python3.6/dist-packages/ray/rllib/agents/ars/ars.py", line 211, in _train
    theta_id, config["num_rollouts"])
  File "/usr/local/lib/python3.6/dist-packages/ray/rllib/agents/ars/ars.py", line 316, in _collect_results
    for result in ray_get_and_free(rollout_ids):
  File "/usr/local/lib/python3.6/dist-packages/ray/rllib/utils/memory.py", line 33, in ray_get_and_free
    result = ray.get(object_ids)
ray.exceptions.RayTaskError(ConnectionResetError): [36mray::Worker.do_rollouts()[39m (pid=49909, ip=172.18.0.6)
  File "python/ray/_raylet.pyx", line 636, in ray._raylet.execute_task
  File "python/ray/_raylet.pyx", line 619, in ray._raylet.execute_task.function_executor
  File "/usr/local/lib/python3.6/dist-packages/ray/rllib/agents/ars/ars.py", line 143, in do_rollouts
    rewards_neg, lengths_neg = self.rollout(timestep_limit)
  File "/usr/local/lib/python3.6/dist-packages/ray/rllib/agents/ars/ars.py", line 112, in rollout
    offset=self.config["offset"])
  File "/usr/local/lib/python3.6/dist-packages/ray/rllib/agents/ars/policies.py", line 49, in rollout
    observation, rew, done, _ = env.step(ac)
  File "/root/hany606/Tensegrity-Robotics/src/dev/gym-tensegrity/gym_tensegrity/envs/jumper_env.py", line 206, in step
    self._takeAction(action)
  File "/root/hany606/Tensegrity-Robotics/src/dev/gym-tensegrity/gym_tensegrity/envs/jumper_env.py", line 232, in _takeAction
    self.env.step()
  File "/root/hany606/Tensegrity-Robotics/src/dev/gym-tensegrity/gym_tensegrity/envs/jumper_model.py", line 164, in step
    sim_raw_data = self.read()
  File "/root/hany606/Tensegrity-Robotics/src/dev/gym-tensegrity/gym_tensegrity/envs/jumper_model.py", line 111, in read
    data.append(self.connection.recv(self.packet_size).decode("utf-8"))         #reading part
ConnectionResetError: [Errno 104] Connection reset by peer

During handling of the above exception, another exception occurred:

[36mray::ARSTrainer.train()[39m (pid=49956, ip=172.18.0.6)
  File "python/ray/_raylet.pyx", line 633, in ray._raylet.execute_task
  File "python/ray/_raylet.pyx", line 634, in ray._raylet.execute_task
  File "python/ray/_raylet.pyx", line 636, in ray._raylet.execute_task
  File "python/ray/_raylet.pyx", line 619, in ray._raylet.execute_task.function_executor
  File "/usr/local/lib/python3.6/dist-packages/ray/rllib/agents/trainer.py", line 438, in train
    self._try_recover()
  File "/usr/local/lib/python3.6/dist-packages/ray/rllib/agents/trainer.py", line 799, in _try_recover
    "Recovery is not supported for this algorithm")
NotImplementedError: Recovery is not supported for this algorithm

